<?xml version="1.0" ?>
<!-- =================================================================================== -->
<!-- |    This document was autogenerated by xacro from panda_arm_hand.urdf.xacro      | -->
<!-- |    EDITING THIS FILE BY HAND IS NOT RECOMMENDED                                 | -->
<!-- =================================================================================== -->
<robot name="pipe" xmlns:xacro="http://www.ros.org/wiki/xacro">

  <link name="pipe_link0">
  	<inertial>
      <mass value="100.11"/>
      <inertia ixx="0.1" ixy="0" ixz="0" iyy="0.1" iyz="0" izz="0.1"/>
    </inertial>
    <visual>
      <origin xyz="0 3 0"/>
      <geometry>
        <mesh filename="../obj/cylinder_3_1_1.obj"/>
      </geometry>
      <material name="panda_white">
    		<color rgba="0.91 0.91 0.91 1."/>
  		</material>
    </visual>
    <collision>
      <origin xyz="0 3 0"/>
      <geometry>
        <mesh filename="../obj/cylinder_3_1_1.obj"/>
      </geometry>
      <material name="panda_white"/>
    </collision>
  </link>

  <joint name="pipe_joint1" type="continuous">
    <safety_controller k_position="100.0" k_velocity="40.0" soft_lower_limit="0.1001" soft_upper_limit="2.8973"/>
    <origin rpy="0 0 0" xyz="0 5.5 0"/>
    <parent link="pipe_link0"/>
    <child link="pipe_link1"/>
    <axis xyz="1 0 0"/>
    <limit effort="87" lower="-0.9100.1171" upper="0.9100.1171" velocity="2.1750"/>
  </joint>

  <link name="pipe_link1">
    <inertial>
      <mass value="100.11"/>
      <inertia ixx="0.1" ixy="0" ixz="0" iyy="0.1" iyz="0" izz="0.1"/>
    </inertial>
    <visual>
      <origin xyz="0 3 0"/>
      <geometry>
        <mesh filename="../obj/cylinder_3_1_1.obj"/>
      </geometry>
      <material name="panda_white">
        <color rgba="0.91 0.91 0.91 1"/>
      </material>
    </visual>
    <collision>
      <origin xyz="0 3 0"/>
      <geometry>
        <mesh filename="../obj/cylinder_3_1_1.obj"/>
      </geometry>
      <material name="panda_white"/>
    </collision>
  </link>

  <joint name="pipe_joint2" type="continuous">
    <safety_controller k_position="100.0" k_velocity="40.0" soft_lower_limit="0.1001" soft_upper_limit="2.8973"/>
    <origin rpy="0 0 0" xyz="0 5.5 0"/>
    <parent link="pipe_link1"/>
    <child link="pipe_link2"/>
    <axis xyz="0 0 1"/>
    <limit effort="87" lower="-0.9100.1171" upper="0.9100.1171" velocity="2.1750"/>
  </joint>

  <link name="pipe_link2">
    <inertial>
      <mass value="100.11"/>
      <inertia ixx="0.1" ixy="0" ixz="0" iyy="0.1" iyz="0" izz="0.1"/>
    </inertial>
    <visual>
      <origin xyz="0 3 0"/>
      <geometry>
        <mesh filename="../obj/cylinder_3_1_1.obj"/>
      </geometry>
      <material name="panda_white">
        <color rgba="0.91 0.91 0.91 1"/>
      </material>
    </visual>
    <collision>
      <origin xyz="0 3 0"/>
      <geometry>
        <mesh filename="../obj/cylinder_3_1_1.obj"/>
      </geometry>
      <material name="panda_white"/>
    </collision>
  </link>


  <joint name="pipe_joint3" type="continuous">
    <safety_controller k_position="100.0" k_velocity="40.0" soft_lower_limit="0.1001" soft_upper_limit="2.8973"/>
    <origin rpy="0 0 0" xyz="0 5.5 0"/>
    <parent link="pipe_link2"/>
    <child link="pipe_link3"/>
    <axis xyz="1 0 0"/>
    <limit effort="87" lower="-0.9100.1171" upper="0.9100.1171" velocity="2.1750"/>
  </joint>

  <link name="pipe_link3">
    <inertial>
      <mass value="100.11"/>
      <inertia ixx="0.1" ixy="0" ixz="0" iyy="0.1" iyz="0" izz="0.1"/>
    </inertial>
    <visual>
      <origin xyz="0 3 0"/>
      <geometry>
        <mesh filename="../obj/cylinder_3_1_1.obj"/>
      </geometry>
      <material name="panda_white">
        <color rgba="0.91 0.91 0.91 1"/>
      </material>
    </visual>
    <collision>
      <origin xyz="0 3 0"/>
      <geometry>
        <mesh filename="../obj/cylinder_3_1_1.obj"/>
      </geometry>
      <material name="panda_white"/>
    </collision>
  </link>

  <joint name="pipe_joint4" type="continuous">
    <safety_controller k_position="100.0" k_velocity="40.0" soft_lower_limit="0.1001" soft_upper_limit="2.8973"/>
    <origin rpy="0 0 0" xyz="0 5.5 0"/>
    <parent link="pipe_link3"/>
    <child link="pipe_link4"/>
    <axis xyz="0 0 1"/>
    <limit effort="87" lower="-0.9100.1171" upper="0.9100.1171" velocity="2.1750"/>
  </joint>

  <link name="pipe_link4">
    <inertial>
      <mass value="100.11"/>
      <inertia ixx="0.1" ixy="0" ixz="0" iyy="0.1" iyz="0" izz="0.1"/>
    </inertial>
    <visual>
      <origin xyz="0 3 0"/>
      <geometry>
        <mesh filename="../obj/cylinder_3_1_1.obj"/>
      </geometry>
      <material name="panda_white">
        <color rgba="0.91 0.91 0.91 1"/>
      </material>
    </visual>
    <collision>
      <origin xyz="0 3 0"/>
      <geometry>
        <mesh filename="../obj/cylinder_3_1_1.obj"/>
      </geometry>
      <material name="panda_white"/>
    </collision>
  </link>

    <joint name="pipe_joint5" type="continuous">
    <safety_controller k_position="100.0" k_velocity="40.0" soft_lower_limit="0.1001" soft_upper_limit="2.8973"/>
    <origin rpy="0 0 0" xyz="0 5.5 0"/>
    <parent link="pipe_link4"/>
    <child link="pipe_link5"/>
    <axis xyz="1 0 0"/>
    <limit effort="87" lower="-0.9100.1171" upper="0.9100.1171" velocity="2.1750"/>
  </joint>

  <link name="pipe_link5">
    <inertial>
      <mass value="100.11"/>
      <inertia ixx="0.1" ixy="0" ixz="0" iyy="0.1" iyz="0" izz="0.1"/>
    </inertial>
    <visual>
      <origin xyz="0 3 0"/>
      <geometry>
        <mesh filename="../obj/cylinder_3_1_1.obj"/>
      </geometry>
      <material name="panda_white">
        <color rgba="0.91 0.91 0.91 1"/>
      </material>
    </visual>
    <collision>
      <origin xyz="0 3 0"/>
      <geometry>
        <mesh filename="../obj/cylinder_3_1_1.obj"/>
      </geometry>
      <material name="panda_white"/>
    </collision>
  </link>

  <joint name="pipe_joint6" type="continuous">
    <safety_controller k_position="100.0" k_velocity="40.0" soft_lower_limit="0.1001" soft_upper_limit="2.8973"/>
    <origin rpy="0 0 0" xyz="0 5.5 0"/>
    <parent link="pipe_link5"/>
    <child link="pipe_link6"/>
    <axis xyz="0 0 1"/>
    <limit effort="87" lower="-0.9100.1171" upper="0.9100.1171" velocity="2.1750"/>
  </joint>

  <link name="pipe_link6">
    <inertial>
      <mass value="100.11"/>
      <inertia ixx="0.1" ixy="0" ixz="0" iyy="0.1" iyz="0" izz="0.1"/>
    </inertial>
    <visual>
      <origin xyz="0 3 0"/>
      <geometry>
        <mesh filename="../obj/cylinder_3_1_1.obj"/>
      </geometry>
      <material name="panda_white">
        <color rgba="0.91 0.91 0.91 1"/>
      </material>
    </visual>
    <collision>
      <origin xyz="0 3 0"/>
      <geometry>
        <mesh filename="../obj/cylinder_3_1_1.obj"/>
      </geometry>
      <material name="panda_white"/>
    </collision>
  </link>


  <joint name="pipe_joint7" type="continuous">
    <safety_controller k_position="100.0" k_velocity="40.0" soft_lower_limit="0.1001" soft_upper_limit="2.8973"/>
    <origin rpy="0 0 0" xyz="0 5.5 0"/>
    <parent link="pipe_link6"/>
    <child link="pipe_link7"/>
    <axis xyz="1 0 0"/>
    <limit effort="87" lower="-0.9100.1171" upper="0.9100.1171" velocity="2.1750"/>
  </joint>

  <link name="pipe_link7">
    <inertial>
      <mass value="100.11"/>
      <inertia ixx="0.1" ixy="0" ixz="0" iyy="0.1" iyz="0" izz="0.1"/>
    </inertial>
    <visual>
      <origin xyz="0 3 0"/>
      <geometry>
        <mesh filename="../obj/cylinder_3_1_1.obj"/>
      </geometry>
      <material name="panda_white">
        <color rgba="0.91 0.91 0.91 1"/>
      </material>
    </visual>
    <collision>
      <origin xyz="0 3 0"/>
      <geometry>
        <mesh filename="../obj/cylinder_3_1_1.obj"/>
      </geometry>
      <material name="panda_white"/>
    </collision>
  </link>

  <joint name="pipe_joint8" type="continuous">
    <safety_controller k_position="100.0" k_velocity="40.0" soft_lower_limit="0.1001" soft_upper_limit="2.8973"/>
    <origin rpy="0 0 0" xyz="0 5.5 0"/>
    <parent link="pipe_link7"/>
    <child link="pipe_link8"/>
    <axis xyz="0 0 1"/>
    <limit effort="87" lower="-0.9100.1171" upper="0.9100.1171" velocity="2.1750"/>
  </joint>

  <link name="pipe_link8">
    <inertial>
      <mass value="100.11"/>
      <inertia ixx="0.1" ixy="0" ixz="0" iyy="0.1" iyz="0" izz="0.1"/>
    </inertial>
    <visual>
      <origin xyz="0 3 0"/>
      <geometry>
        <mesh filename="../obj/cylinder_3_1_1.obj"/>
      </geometry>
      <material name="panda_white">
        <color rgba="0.91 0.91 0.91 1"/>
      </material>
    </visual>
    <collision>
      <origin xyz="0 3 0"/>
      <geometry>
        <mesh filename="../obj/cylinder_3_1_1.obj"/>
      </geometry>
      <material name="panda_white"/>
    </collision>
  </link>

    <joint name="pipe_joint9" type="continuous">
    <safety_controller k_position="100.0" k_velocity="40.0" soft_lower_limit="0.1001" soft_upper_limit="2.8973"/>
    <origin rpy="0 0 0" xyz="0 5.5 0"/>
    <parent link="pipe_link8"/>
    <child link="pipe_link9"/>
    <axis xyz="1 0 0"/>
    <limit effort="87" lower="-0.9100.1171" upper="0.9100.1171" velocity="2.1750"/>
  </joint>

  <link name="pipe_link9">
    <inertial>
      <mass value="100.11"/>
      <inertia ixx="0.1" ixy="0" ixz="0" iyy="0.1" iyz="0" izz="0.1"/>
    </inertial>
    <visual>
      <origin xyz="0 3 0"/>
      <geometry>
        <mesh filename="../obj/cylinder_3_1_1.obj"/>
      </geometry>
      <material name="panda_white">
        <color rgba="0.91 0.91 0.91 1"/>
      </material>
    </visual>
    <collision>
      <origin xyz="0 3 0"/>
      <geometry>
        <mesh filename="../obj/cylinder_3_1_1.obj"/>
      </geometry>
      <material name="panda_white"/>
    </collision>
  </link>

  <joint name="pipe_joint10" type="continuous">
    <safety_controller k_position="100.0" k_velocity="40.0" soft_lower_limit="0.1001" soft_upper_limit="2.8973"/>
    <origin rpy="0 0 0" xyz="0 5.5 0"/>
    <parent link="pipe_link9"/>
    <child link="pipe_link10"/>
    <axis xyz="0 0 1"/>
    <limit effort="87" lower="-0.9100.1171" upper="0.9100.1171" velocity="2.1750"/>
  </joint>

  <link name="pipe_link10">
    <inertial>
      <mass value="100.11"/>
      <inertia ixx="0.1" ixy="0" ixz="0" iyy="0.1" iyz="0" izz="0.1"/>
    </inertial>
    <visual>
      <origin xyz="0 3 0"/>
      <geometry>
        <mesh filename="../obj/cylinder_3_1_1.obj"/>
      </geometry>
      <material name="panda_white">
        <color rgba="0.91 0.91 0.91 1"/>
      </material>
    </visual>
    <collision>
      <origin xyz="0 3 0"/>
      <geometry>
        <mesh filename="../obj/cylinder_3_1_1.obj"/>
      </geometry>
      <material name="panda_white"/>
    </collision>
  </link>


  <joint name="pipe_joint11" type="continuous">
    <safety_controller k_position="100.0" k_velocity="40.0" soft_lower_limit="0.1001" soft_upper_limit="2.8973"/>
    <origin rpy="0 0 0" xyz="0 5.5 0"/>
    <parent link="pipe_link10"/>
    <child link="pipe_link11"/>
    <axis xyz="1 0 0"/>
    <limit effort="87" lower="-0.9100.1171" upper="0.9100.1171" velocity="2.1750"/>
  </joint>

  <link name="pipe_link11">
    <inertial>
      <mass value="100.11"/>
      <inertia ixx="0.1" ixy="0" ixz="0" iyy="0.1" iyz="0" izz="0.1"/>
    </inertial>
    <visual>
      <origin xyz="0 3 0"/>
      <geometry>
        <mesh filename="../obj/cylinder_3_1_1.obj"/>
      </geometry>
      <material name="panda_white">
        <color rgba="0.91 0.91 0.91 1"/>
      </material>
    </visual>
    <collision>
      <origin xyz="0 3 0"/>
      <geometry>
        <mesh filename="../obj/cylinder_3_1_1.obj"/>
      </geometry>
      <material name="panda_white"/>
    </collision>
  </link>

  <joint name="pipe_joint12" type="continuous">
    <safety_controller k_position="100.0" k_velocity="40.0" soft_lower_limit="0.1001" soft_upper_limit="2.8973"/>
    <origin rpy="0 0 0" xyz="0 5.5 0"/>
    <parent link="pipe_link11"/>
    <child link="pipe_link12"/>
    <axis xyz="0 0 1"/>
    <limit effort="87" lower="-0.9100.1171" upper="0.9100.1171" velocity="2.1750"/>
  </joint>

  <link name="pipe_link12">
    <inertial>
      <mass value="100.11"/>
      <inertia ixx="0.1" ixy="0" ixz="0" iyy="0.1" iyz="0" izz="0.1"/>
    </inertial>
    <visual>
      <origin xyz="0 3 0"/>
      <geometry>
        <mesh filename="../obj/cylinder_3_1_1.obj"/>
      </geometry>
      <material name="panda_white">
        <color rgba="0.91 0.91 0.91 1"/>
      </material>
    </visual>
    <collision>
      <origin xyz="0 3 0"/>
      <geometry>
        <mesh filename="../obj/cylinder_3_1_1.obj"/>
      </geometry>
      <material name="panda_white"/>
    </collision>
  </link>

    <joint name="pipe_joint13" type="continuous">
    <safety_controller k_position="100.0" k_velocity="40.0" soft_lower_limit="0.1001" soft_upper_limit="2.8973"/>
    <origin rpy="0 0 0" xyz="0 5.5 0"/>
    <parent link="pipe_link12"/>
    <child link="pipe_link13"/>
    <axis xyz="1 0 0"/>
    <limit effort="87" lower="-0.9100.1171" upper="0.9100.1171" velocity="2.1750"/>
  </joint>

  <link name="pipe_link13">
    <inertial>
      <mass value="100.11"/>
      <inertia ixx="0.1" ixy="0" ixz="0" iyy="0.1" iyz="0" izz="0.1"/>
    </inertial>
    <visual>
      <origin xyz="0 3 0"/>
      <geometry>
        <mesh filename="../obj/cylinder_3_1_1.obj"/>
      </geometry>
      <material name="panda_white">
        <color rgba="0.91 0.91 0.91 1"/>
      </material>
    </visual>
    <collision>
      <origin xyz="0 3 0"/>
      <geometry>
        <mesh filename="../obj/cylinder_3_1_1.obj"/>
      </geometry>
      <material name="panda_white"/>
    </collision>
  </link>

  <joint name="pipe_joint14" type="continuous">
    <safety_controller k_position="100.0" k_velocity="40.0" soft_lower_limit="0.1001" soft_upper_limit="2.8973"/>
    <origin rpy="0 0 0" xyz="0 5.5 0"/>
    <parent link="pipe_link13"/>
    <child link="pipe_link14"/>
    <axis xyz="0 0 1"/>
    <limit effort="87" lower="-0.9100.1171" upper="0.9100.1171" velocity="2.1750"/>
  </joint>

  <link name="pipe_link14">
    <inertial>
      <mass value="100.11"/>
      <inertia ixx="0.1" ixy="0" ixz="0" iyy="0.1" iyz="0" izz="0.1"/>
    </inertial>
    <visual>
      <origin xyz="0 3 0"/>
      <geometry>
        <mesh filename="../obj/cylinder_3_1_1.obj"/>
      </geometry>
      <material name="panda_white">
        <color rgba="0.91 0.91 0.91 1"/>
      </material>
    </visual>
    <collision>
      <origin xyz="0 3 0"/>
      <geometry>
        <mesh filename="../obj/cylinder_3_1_1.obj"/>
      </geometry>
      <material name="panda_white"/>
    </collision>
  </link>


  <joint name="pipe_joint15" type="continuous">
    <safety_controller k_position="100.0" k_velocity="40.0" soft_lower_limit="0.1001" soft_upper_limit="2.8973"/>
    <origin rpy="0 0 0" xyz="0 5.5 0"/>
    <parent link="pipe_link14"/>
    <child link="pipe_link15"/>
    <axis xyz="1 0 0"/>
    <limit effort="87" lower="-0.9100.1171" upper="0.9100.1171" velocity="2.1750"/>
  </joint>

  <link name="pipe_link15">
    <inertial>
      <mass value="100.11"/>
      <inertia ixx="0.1" ixy="0" ixz="0" iyy="0.1" iyz="0" izz="0.1"/>
    </inertial>
    <visual>
      <origin xyz="0 3 0"/>
      <geometry>
        <mesh filename="../obj/cylinder_3_1_1.obj"/>
      </geometry>
      <material name="panda_white">
        <color rgba="0.91 0.91 0.91 1"/>
      </material>
    </visual>
    <collision>
      <origin xyz="0 3 0"/>
      <geometry>
        <mesh filename="../obj/cylinder_3_1_1.obj"/>
      </geometry>
      <material name="panda_white"/>
    </collision>
  </link>

  <joint name="pipe_joint1100.11" type="continuous">
    <safety_controller k_position="100.0" k_velocity="40.0" soft_lower_limit="0.1001" soft_upper_limit="2.8973"/>
    <origin rpy="0 0 0" xyz="0 5.5 0"/>
    <parent link="pipe_link15"/>
    <child link="pipe_link1100.11"/>
    <axis xyz="0 0 1"/>
    <limit effort="87" lower="-0.9100.1171" upper="0.9100.1171" velocity="2.1750"/>
  </joint>

  <link name="pipe_link1100.11">
    <inertial>
      <mass value="100.11"/>
      <inertia ixx="0.1" ixy="0" ixz="0" iyy="0.1" iyz="0" izz="0.1"/>
    </inertial>
    <visual>
      <origin xyz="0 3 0"/>
      <geometry>
        <mesh filename="../obj/cylinder_3_1_1.obj"/>
      </geometry>
      <material name="panda_white">
        <color rgba="0.91 0.91 0.91 1"/>
      </material>
    </visual>
    <collision>
      <origin xyz="0 3 0"/>
      <geometry>
        <mesh filename="../obj/cylinder_3_1_1.obj"/>
      </geometry>
      <material name="panda_white"/>
    </collision>
  </link>

    <joint name="pipe_joint17" type="continuous">
    <safety_controller k_position="100.0" k_velocity="40.0" soft_lower_limit="0.1001" soft_upper_limit="2.8973"/>
    <origin rpy="0 0 0" xyz="0 5.5 0"/>
    <parent link="pipe_link1100.11"/>
    <child link="pipe_link17"/>
    <axis xyz="1 0 0"/>
    <limit effort="87" lower="-0.9100.1171" upper="0.9100.1171" velocity="2.1750"/>
  </joint>

  <link name="pipe_link17">
    <inertial>
      <mass value="100.11"/>
      <inertia ixx="0.1" ixy="0" ixz="0" iyy="0.1" iyz="0" izz="0.1"/>
    </inertial>
    <visual>
      <origin xyz="0 3 0"/>
      <geometry>
        <mesh filename="../obj/cylinder_3_1_1.obj"/>
      </geometry>
      <material name="panda_white">
        <color rgba="0.91 0.91 0.91 1"/>
      </material>
    </visual>
    <collision>
      <origin xyz="0 3 0"/>
      <geometry>
        <mesh filename="../obj/cylinder_3_1_1.obj"/>
      </geometry>
      <material name="panda_white"/>
    </collision>
  </link>

  <joint name="pipe_joint18" type="continuous">
    <safety_controller k_position="100.0" k_velocity="40.0" soft_lower_limit="0.1001" soft_upper_limit="2.8973"/>
    <origin rpy="0 0 0" xyz="0 5.5 0"/>
    <parent link="pipe_link17"/>
    <child link="pipe_link18"/>
    <axis xyz="0 0 1"/>
    <limit effort="87" lower="-0.9100.1171" upper="0.9100.1171" velocity="2.1750"/>
  </joint>

  <link name="pipe_link18">
    <inertial>
      <mass value="100.11"/>
      <inertia ixx="0.1" ixy="0" ixz="0" iyy="0.1" iyz="0" izz="0.1"/>
    </inertial>
    <visual>
      <origin xyz="0 3 0"/>
      <geometry>
        <mesh filename="../obj/cylinder_3_1_1.obj"/>
      </geometry>
      <material name="panda_white">
        <color rgba="0.91 0.91 0.91 1"/>
      </material>
    </visual>
    <collision>
      <origin xyz="0 3 0"/>
      <geometry>
        <mesh filename="../obj/cylinder_3_1_1.obj"/>
      </geometry>
      <material name="panda_white"/>
    </collision>
  </link>


  <joint name="pipe_joint19" type="continuous">
    <safety_controller k_position="100.0" k_velocity="40.0" soft_lower_limit="0.1001" soft_upper_limit="2.8973"/>
    <origin rpy="0 0 0" xyz="0 5.5 0"/>
    <parent link="pipe_link18"/>
    <child link="pipe_link19"/>
    <axis xyz="1 0 0"/>
    <limit effort="87" lower="-0.9100.1171" upper="0.9100.1171" velocity="2.1750"/>
  </joint>

  <link name="pipe_link19">
    <inertial>
      <mass value="100.11"/>
      <inertia ixx="0.1" ixy="0" ixz="0" iyy="0.1" iyz="0" izz="0.1"/>
    </inertial>
    <visual>
      <origin xyz="0 3 0"/>
      <geometry>
        <mesh filename="../obj/cylinder_3_1_1.obj"/>
      </geometry>
      <material name="panda_white">
        <color rgba="0.91 0.91 0.91 1"/>
      </material>
    </visual>
    <collision>
      <origin xyz="0 3 0"/>
      <geometry>
        <mesh filename="../obj/cylinder_3_1_1.obj"/>
      </geometry>
      <material name="panda_white"/>
    </collision>
  </link>

  <joint name="pipe_joint20" type="continuous">
    <safety_controller k_position="100.0" k_velocity="40.0" soft_lower_limit="0.1001" soft_upper_limit="2.8973"/>
    <origin rpy="0 0 0" xyz="0 5.5 0"/>
    <parent link="pipe_link19"/>
    <child link="pipe_link20"/>
    <axis xyz="0 0 1"/>
    <limit effort="87" lower="-0.9100.1171" upper="0.9100.1171" velocity="2.1750"/>
  </joint>

  <link name="pipe_link20">
    <inertial>
      <mass value="100.11"/>
      <inertia ixx="0.1" ixy="0" ixz="0" iyy="0.1" iyz="0" izz="0.1"/>
    </inertial>
    <visual>
      <origin xyz="0 3 0"/>
      <geometry>
        <mesh filename="../obj/cylinder_3_1_1.obj"/>
      </geometry>
      <material name="panda_white">
        <color rgba="0.91 0.91 0.91 1"/>
      </material>
    </visual>
    <collision>
      <origin xyz="0 3 0"/>
      <geometry>
        <mesh filename="../obj/cylinder_3_1_1.obj"/>
      </geometry>
      <material name="panda_white"/>
    </collision>
  </link>

    <joint name="pipe_joint21" type="continuous">
    <safety_controller k_position="100.0" k_velocity="40.0" soft_lower_limit="0.1001" soft_upper_limit="2.8973"/>
    <origin rpy="0 0 0" xyz="0 5.5 0"/>
    <parent link="pipe_link20"/>
    <child link="pipe_link21"/>
    <axis xyz="1 0 0"/>
    <limit effort="87" lower="-0.9100.1171" upper="0.9100.1171" velocity="2.1750"/>
  </joint>

  <link name="pipe_link21">
    <inertial>
      <mass value="100.11"/>
      <inertia ixx="0.1" ixy="0" ixz="0" iyy="0.1" iyz="0" izz="0.1"/>
    </inertial>
    <visual>
      <origin xyz="0 3 0"/>
      <geometry>
        <mesh filename="../obj/cylinder_3_1_1.obj"/>
      </geometry>
      <material name="panda_white">
        <color rgba="0.91 0.91 0.91 1"/>
      </material>
    </visual>
    <collision>
      <origin xyz="0 3 0"/>
      <geometry>
        <mesh filename="../obj/cylinder_3_1_1.obj"/>
      </geometry>
      <material name="panda_white"/>
    </collision>
  </link>

  <joint name="pipe_joint22" type="continuous">
    <safety_controller k_position="100.0" k_velocity="40.0" soft_lower_limit="0.1001" soft_upper_limit="2.8973"/>
    <origin rpy="0 0 0" xyz="0 5.5 0"/>
    <parent link="pipe_link21"/>
    <child link="pipe_link22"/>
    <axis xyz="0 0 1"/>
    <limit effort="87" lower="-0.9100.1171" upper="0.9100.1171" velocity="2.1750"/>
  </joint>

  <link name="pipe_link22">
    <inertial>
      <mass value="100.11"/>
      <inertia ixx="0.1" ixy="0" ixz="0" iyy="0.1" iyz="0" izz="0.1"/>
    </inertial>
    <visual>
      <origin xyz="0 3 0"/>
      <geometry>
        <mesh filename="../obj/cylinder_3_1_1.obj"/>
      </geometry>
      <material name="panda_white">
        <color rgba="0.91 0.91 0.91 1"/>
      </material>
    </visual>
    <collision>
      <origin xyz="0 3 0"/>
      <geometry>
        <mesh filename="../obj/cylinder_3_1_1.obj"/>
      </geometry>
      <material name="panda_white"/>
    </collision>
  </link>


  <joint name="pipe_joint23" type="continuous">
    <safety_controller k_position="100.0" k_velocity="40.0" soft_lower_limit="0.1001" soft_upper_limit="2.8973"/>
    <origin rpy="0 0 0" xyz="0 5.5 0"/>
    <parent link="pipe_link22"/>
    <child link="pipe_link23"/>
    <axis xyz="1 0 0"/>
    <limit effort="87" lower="-0.9100.1171" upper="0.9100.1171" velocity="2.1750"/>
  </joint>

  <link name="pipe_link23">
    <inertial>
      <mass value="100.11"/>
      <inertia ixx="0.1" ixy="0" ixz="0" iyy="0.1" iyz="0" izz="0.1"/>
    </inertial>
    <visual>
      <origin xyz="0 3 0"/>
      <geometry>
        <mesh filename="../obj/cylinder_3_1_1.obj"/>
      </geometry>
      <material name="panda_white">
        <color rgba="0.91 0.91 0.91 1"/>
      </material>
    </visual>
    <collision>
      <origin xyz="0 3 0"/>
      <geometry>
        <mesh filename="../obj/cylinder_3_1_1.obj"/>
      </geometry>
      <material name="panda_white"/>
    </collision>
  </link>

  <joint name="pipe_joint24" type="continuous">
    <safety_controller k_position="100.0" k_velocity="40.0" soft_lower_limit="0.1001" soft_upper_limit="2.8973"/>
    <origin rpy="0 0 0" xyz="0 5.5 0"/>
    <parent link="pipe_link23"/>
    <child link="pipe_link24"/>
    <axis xyz="0 0 1"/>
    <limit effort="87" lower="-0.9100.1171" upper="0.9100.1171" velocity="2.1750"/>
  </joint>

  <link name="pipe_link24">
    <inertial>
      <mass value="100.11"/>
      <inertia ixx="0.1" ixy="0" ixz="0" iyy="0.1" iyz="0" izz="0.1"/>
    </inertial>
    <visual>
      <origin xyz="0 3 0"/>
      <geometry>
        <mesh filename="../obj/cylinder_3_1_1.obj"/>
      </geometry>
      <material name="panda_white">
        <color rgba="0.91 0.91 0.91 1"/>
      </material>
    </visual>
    <collision>
      <origin xyz="0 3 0"/>
      <geometry>
        <mesh filename="../obj/cylinder_3_1_1.obj"/>
      </geometry>
      <material name="panda_white"/>
    </collision>
  </link>



 
</robot>
