<?xml version="1.0" ?>
<robot name="charge_board">
    <link name="world"/>
    <link name="door" >
        <visual>
            <origin xyz="0.04 0 0" rpy="1.57079632679 0 0" />
            <geometry>
                <cylinder radius="0.04" length="0.01" />
            </geometry>
        </visual>
        <collision>
            <origin xyz="0.04 0 0" rpy="1.57079632679 0 0" />
            <geometry>
                <cylinder radius="0.04" length="0.01" />
            </geometry>
        </collision>
        <inertial>
            <origin rpy="0 0 0" xyz="0 0 0"/>
            <mass value="1.0"/>
            <inertia ixx="0.048966669" ixy="0" ixz="0" iyy="0.046466667" iyz="0" izz="0.0041666669"/>
        </inertial>
    </link>
    <link name="door_base">
        <inertial>
            <origin rpy="0 0 0" xyz="0 0 0"/>
            <mass value="1.0"/>
            <inertia ixx="1" ixy="0" ixz="0" iyy="1" iyz="0" izz="1"/>
        </inertial>
    </link>
    <joint name="fixed" type="fixed">
        <parent link="world"/>
        <child link="door_base"/>
        <origin xyz="0.04 0 0"/>
    </joint>
    <joint name="door_hinge" type="revolute">
        <parent link="door_base"/>
        <child link="door"/>
        <dynamics damping="1.0" friction="0.0001"/>
        <origin xyz="0.0 0 0"/>
		<axis xyz="0 0 1"/>
        <limit lower="-2.09439510239" upper="0" />
    </joint>
</robot>